Workbook

Sheet Worklog_Tasks&Times
A1: Date | B1: Status | C1: Task | D1: Description/Planning | E1: Task Type | F1: Most suited ILO | G1: Est Hours | H1: Actual Hours | I1: Diff | J1: Evidence link | K1: Task reflection / notes
A2: Week 1
A3: week plan: | B3: - Weekplan item 1 - Weekplan item 2 - Weekplan item 3 - etc
A4: Known Risks | B4: [Enter known possible issues that are a risk for you to finish the high level week planning]
A5: 45538 | B5: Done | C5: watching movie | D5: We watched Minority report movie which was about the crime which police use psychic technology to stopped the crime and arrest murder before they commit a crime . | E5: Meeting | F5: ILO 3.1 | G5: 2 | H5: 3.45 | I5: =H5-G5 -> 1.45
A6: 45537 | B6: Done | C6: First Meeting of AI and data science | D6: We was there to get information about this course and to be familiar with our python and math teachers and get to know that when we don't feel well who we can met. | E6: Meeting | F6: ILO 3.1 | G6: 2 | H6: 1.5 | I6: =H6-G6 -> -0.5
A7: 45538 | B7: Done | C7: Informed about how to use worklog | D7: In our data lab Edirlei and Elavendan came to our class to teach us how to use work log and learning log | E7: Debugging | F7: ILO 3.1 | G7: 0.5 | H7: 0.5 | I7: =H7-G7 -> 0
A8: 45538 | B8: Done | C8: Did the Tuesday quizzes | D8: I did the the Tuesday quizzes based on context that we have it | E8: Study | F8: ILO 3.1 | G8: 1 | H8: 1.3 | I8: =H8-G8 -> 0.3 | J8: https://github.com/BredaUniversityADSAI/2024-25A-FAI1-ADSAI--MohammadaliJaberi244437/blob/main/Quizzes-%20Project%201A%202024-2025%20-%20Breda%20University%20of%20Applied%20Sciences%20(TUESDAY).pdf
A9: 45539 | B9: Done | C9: Monday quizzes | D9: I did the the Monday quizzes with delay because I did not based on what context can I answer the quiestion | E9: Study | F9: ILO 3.1 | G9: 1 | H9: 2 | I9: =H9-G9 -> 1 | J9: https://github.com/BredaUniversityADSAI/2024-25A-FAI1-ADSAI--MohammadaliJaberi244437/blob/main/Quizzes%20-%20Project%201A%202024-2025%20-%20Breda%20University%20of%20Applied%20Sciences%20(Monday).pdf
A10: 45539 | B10: Done | C10: Wednesday quizzes | D10: I did the Wednesday quizzes based on the context we had it was about history of AI and the question that I like it was can machine think ro not. | E10: Study | F10: ILO 3.1 | G10: 1 | H10: 1 | I10: =H10-G10 -> 0 | J10: https://github.com/BredaUniversityADSAI/2024-25A-FAI1-ADSAI--MohammadaliJaberi244437/blob/main/Quizzes%20-%20Project%201A%202024-2025%20-%20Breda%20University%20of%20Applied%20Sciences%20Wednesday.pdf
A11: 45539 | B11: Done | C11: Wednesday text | D11: I read the whole context and based on that I was able to answer 3 questions. | E11: Study | F11: ILO 3.1 | G11: 2 | H11: 2 | I11: =H11-G11 -> 0 | J11: https://adsai.buas.nl/Study%20Content/Artificial%20Intelligence/3.%20History%20of%20AI%20&%20GitHub.html
A12: 37503 | B12: Done | C12: install github | D12: I had a problem to push my files and can use it for the evidence which I solve this | E12: Study | F12: ILO 3.1 | G12: 2 | H12: 3 | I12: =H12-G12 -> 1 | J12: https://github.com/BredaUniversityADSAI/2024-25A-FAI1-ADSAI--MohammadaliJaberi244437 | K12: I did not know how to make a evidence that’s why it tooks more time
A13: 45540 | B13: Done | C13: Reviewing Python | E13: Programming | F13: ILO 0.1 | G13: 2 | H13: 3 | I13: =H13-G13 -> 1 | J13: https://www.w3schools.com/python/default.asp | K13: In back in my country I used a to programing with python and I saw it's our course so I decide to review it to be comfortable in course.
A14: 45540 | B14: Done | C14: did the Python Task | D14: I downloaded and did it on VS code it wasn't that much hard yet I did variable | E14: Programming | F14: ILO 0.1 | G14: 3 | H14: 3 | I14: =H14-G14 -> 0 | J14: https://github.com/BredaUniversityADSAI/2024-25A-FAI1-ADSAI--MohammadaliJaberi244437/blob/main/1.%20Variables.ipynb
A15: 45540 | B15: Done | C15: did the Python Task | D15: I downloaded and did it on VS code it wasn't that much hard yet I did conditions | E15: Programming | F15: ILO 0.1 | G15: 3 | H15: 3 | I15: =H15-G15 -> 0 | J15: https://github.com/BredaUniversityADSAI/2024-25A-FAI1-ADSAI--MohammadaliJaberi244437/blob/main/2.%20Conditional%20execution.ipynb
A16: 45540 | B16: Done | C16: practice coding bat | E16: Programming | F16: ILO 0.1 | G16: 0.5 | H16: 0.5 | I16: =H16-G16 -> 0 | J16: https://github.com/BredaUniversityADSAI/2024-25A-FAI1-ADSAI--MohammadaliJaberi244437/blob/main/first%20Thursday.png
A17: 45540 | B17: Done | C17: practice Hacker | E17: Programming | F17: ILO 0.1 | G17: 0.5 | H17: 1 | I17: =H17-G17 -> 0.5 | J17: https://github.com/BredaUniversityADSAI/2024-25A-FAI1-ADSAI--MohammadaliJaberi244437/blob/main/FIRST%20THURSDAY%20(IF%20AND%20ELSE).png | K17: questions was harder than what I expect
A18: 45541 | B18: Done | C18: Friday quizz | E18: Study | F18: ILO 3.1 | G18: 1.5 | H18: 1.5 | I18: =H18-G18 -> 0 | J18: https://github.com/BredaUniversityADSAI/2024-25A-FAI1-ADSAI--MohammadaliJaberi244437/blob/main/Friday%20Quiz%20first%20week.png
A19: 45541 | B19: Done | C19: Friday Data lab | D19: prepared my data for presentation | E19: Study | F19: ILO 3.1 | G19: 6 | H19: 6 | I19: =H19-G19 -> 0
A20: 45541 | B20: Done | I20: =H20-G20 -> 0
A21: 45544
A22: 45540 | B22: - | I22: =H22-G22 -> 0
E23: Total Hours | G23: =SUM(G5:G22) -> 28 | H23: =SUM(H5:H22) -> 32.75 | I23: =H23-G23 -> 4.75
A24: Week 2
A25: week plan: | B25: - Weekplan item 1 - Weekplan item 2 - Weekplan item 3 - etc
A26: Known Risks | B26: [Enter known possible issues that are a risk for you to finish the high level week planning] - if any
A27: 45542 | B27: Done | C27: Monday math quiz | E27: Study | F27: ILO 0.2 | G27: 2 | H27: 2 | I27: =H27-G27 -> 0 | J27: https://github.com/BredaUniversityADSAI/2024-25A-FAI1-ADSAI--MohammadaliJaberi244437/blob/main/Summary%20-%20Project%201A%202024-2025%20-%20Breda%20University%20of%20Applied%20Sciences%20Fisrt%20math%20quizz.pdf
A28: 45542 | B28: Done | C28: Monday data lab quiz | E28: Study | F28: ILO 3.1 | G28: 1 | H28: 1 | I28: =H28-G28 -> 0 | J28: https://github.com/BredaUniversityADSAI/2024-25A-FAI1-ADSAI--MohammadaliJaberi244437/blob/main/Quizzes%20-%20Project%201A%202024-2025%20-%20Breda%20University%20of%20Applied%20Sciences%20week%202%20Monday.pdf
A29: 45542 | B29: Done | C29: Monday Data lab | E29: Study | F29: ILO 3.1 | G29: 5 | H29: 5 | I29: =H29-G29 -> 0
A30: 45543 | B30: Done | C30: Tuesday quiz | E30: Study | F30: ILO 3.1 | G30: 1 | H30: 1 | I30: =H30-G30 -> 0 | J30: https://github.com/BredaUniversityADSAI/2024-25A-FAI1-ADSAI--MohammadaliJaberi244437/blob/main/Summary%20-%20Project%201A%202024-2025%20-%20Breda%20University%20of%20Applied%20Sciences%20Week%202%20Tuesday.pdf
A31: 45543 | B31: Done | C31: Tuesday Data lab | E31: Study | F31: ILO 3.1 | G31: 6 | H31: 6 | I31: =H31-G31 -> 0
A32: 45544 | B32: Done | C32: Wednesday quizzes | E32: Study | F32: ILO 3.1 | G32: 1 | H32: 1 | I32: =H32-G32 -> 0 | J32: https://github.com/BredaUniversityADSAI/2024-25A-FAI1-ADSAI--MohammadaliJaberi244437/blob/main/Wednesday%20week%202.png
A33: 45544 | B33: Done | C33: Wednesday data lab | E33: Study | F33: ILO 3.1 | G33: 6 | H33: 6 | I33: =H33-G33 -> 0
A34: 45545 | B34: Done | C34: Python pragraming | D34: Function notbook | E34: Programming | F34: ILO 0.1 | G34: 3 | H34: 3 | I34: =H34-G34 -> 0 | J34: https://github.com/BredaUniversityADSAI/2024-25A-FAI1-ADSAI--MohammadaliJaberi244437/blob/main/3.%20Functions%20(1)%20tamrine%20saturday%20anjam%20shode.ipynb
A35: 45545 | B35: Done | C35: Python programing | D35: Loops | E35: Pragraming | F35: ILO 0.1 | G35: 3 | H35: 3 | I35: =H35-G35 -> 0 | J35: https://github.com/BredaUniversityADSAI/2024-25A-FAI1-ADSAI--MohammadaliJaberi244437/blob/main/4.%20Loops%20(2)%20anjam%20shode.ipynb
A36: 45545 | B36: Done | C36: Coding bat | E36: Programming | F36: ILO 0.1 | G36: 1 | H36: 1 | I36: =H36-G36 -> 0
A37: 45546 | B37: Done | C37: Friday quizz | E37: Study | F37: ILO 3.1 | G37: 1 | H37: 1 | I37: =H37-G37 -> 0 | J37: https://github.com/BredaUniversityADSAI/2024-25A-FAI1-ADSAI--MohammadaliJaberi244437/blob/main/friday%20week%202.png
A38: 45546 | B38: Done | C38: presentation | D38: finding data and searching for a good movie for my presentation | E38: Lecture | F38: ILO 3.1 | G38: 2 | H38: 2 | I38: =H38-G38 -> 0
C39: Max 4 hours tasks | I39: =H39-G39 -> 0
C40: Max 4 hours tasks | I40: =H40-G40 -> 0
...

Sheet Overview
B2: Learning Objective | C2: W1 | D2: W2 | E2: W3 | F2: W4 | G2: W5 | H2: W6 | I2: W7 | J2: W8 | K2: Total Hours for objective
B3: ='Drop-downs'!C2 -> - | K3: =SUM(C3:J3) -> 0
B4: ='Drop-downs'!C3 -> ILO 0.1 | C4: {=IFERROR(SUM(_xlfn._xlws.FILTER('Worklog_Tasks&Times'!$H$5:$H$22,'Worklog_Tasks&Times'!$F$5:$F$22=$B4)),0)} -> 10.5 | D4: {=IFERROR(SUM(_xlfn._xlws.FILTER('Worklog_Tasks&Times'!$H$27:$H$44,'Worklog_Tasks&Times'!$F$27:$F$44=$B4)),0)} -> 7 | E4: {=IFERROR(SUM(_xlfn._xlws.FILTER('Worklog_Tasks&Times'!$H$49:$H$62,'Worklog_Tasks&Times'!$F$49:$F$62=$B4)),0)} -> 8 | F4: {=IFERROR(SUM(_xlfn._xlws.FILTER('Worklog_Tasks&Times'!$H$67:$H$88,'Worklog_Tasks&Times'!$F$67:$F$88=$B4)),0)} -> 8 | G4: {=IFERROR(SUM(_xlfn._xlws.FILTER('Worklog_Tasks&Times'!$H$93:$H$105,'Worklog_Tasks&Times'!$F$93:$F$105=$B4)),0)} -> 12 | H4: {=IFERROR(SUM(_xlfn._xlws.FILTER('Worklog_Tasks&Times'!$H$110:$H$119,'Worklog_Tasks&Times'!$F$110:$F$119=$B4)),0)} -> 6 | I4: {=IFERROR(SUM(_xlfn._xlws.FILTER('Worklog_Tasks&Times'!$H$124:$H$133,'Worklog_Tasks&Times'!$F$124:$F$133=$B4)),0)} -> 22 | J4: {=IFERROR(SUM(_xlfn._xlws.FILTER('Worklog_Tasks&Times'!$H$138:$H$147,'Worklog_Tasks&Times'!$F$138:$F$147=$B4)),0)} -> 0 | K4: =SUM(C4:J4) -> 73.5
B5: ='Drop-downs'!C4 -> ILO 0.2 | C5: {=IFERROR(SUM(_xlfn._xlws.FILTER('Worklog_Tasks&Times'!$H$5:$H$22,'Worklog_Tasks&Times'!$F$5:$F$22=$B5)),0)} -> 0 | D5: {=IFERROR(SUM(_xlfn._xlws.FILTER('Worklog_Tasks&Times'!$H$27:$H$44,'Worklog_Tasks&Times'!$F$27:$F$44=$B5)),0)} -> 2 | E5: {=IFERROR(SUM(_xlfn._xlws.FILTER('Worklog_Tasks&Times'!$H$49:$H$62,'Worklog_Tasks&Times'!$F$49:$F$62=$B5)),0)} -> 2 | F5: {=IFERROR(SUM(_xlfn._xlws.FILTER('Worklog_Tasks&Times'!$H$67:$H$88,'Worklog_Tasks&Times'!$F$67:$F$88=$B5)),0)} -> 1.5 | G5: {=IFERROR(SUM(_xlfn._xlws.FILTER('Worklog_Tasks&Times'!$H$93:$H$105,'Worklog_Tasks&Times'!$F$93:$F$105=$B5)),0)} -> 5.5 | H5: {=IFERROR(SUM(_xlfn._xlws.FILTER('Worklog_Tasks&Times'!$H$110:$H$119,'Worklog_Tasks&Times'!$F$110:$F$119=$B5)),0)} -> 13.5 | I5: {=IFERROR(SUM(_xlfn._xlws.FILTER('Worklog_Tasks&Times'!$H$124:$H$133,'Worklog_Tasks&Times'!$F$124:$F$133=$B5)),0)} -> 0 | J5: {=IFERROR(SUM(_xlfn._xlws.FILTER('Worklog_Tasks&Times'!$H$138:$H$147,'Worklog_Tasks&Times'!$F$138:$F$147=$B5)),0)} -> 0 | K5: =SUM(C5:J5) -> 24.5
B6: ='Drop-downs'!C5 -> ILO 1.1 | C6: {=IFERROR(SUM(_xlfn._xlws.FILTER('Worklog_Tasks&Times'!$H$5:$H$22,'Worklog_Tasks&Times'!$F$5:$F$22=$B6)),0)} -> 0 | D6: {=IFERROR(SUM(_xlfn._xlws.FILTER('Worklog_Tasks&Times'!$H$27:$H$44,'Worklog_Tasks&Times'!$F$27:$F$44=$B6)),0)} -> 0 | E6: {=IFERROR(SUM(_xlfn._xlws.FILTER('Worklog_Tasks&Times'!$H$49:$H$62,'Worklog_Tasks&Times'!$F$49:$F$62=$B6)),0)} -> 0 | F6: {=IFERROR(SUM(_xlfn._xlws.FILTER('Worklog_Tasks&Times'!$H$67:$H$88,'Worklog_Tasks&Times'!$F$67:$F$88=$B6)),0)} -> 0 | G6: {=IFERROR(SUM(_xlfn._xlws.FILTER('Worklog_Tasks&Times'!$H$93:$H$105,'Worklog_Tasks&Times'!$F$93:$F$105=$B6)),0)} -> 0 | H6: {=IFERROR(SUM(_xlfn._xlws.FILTER('Worklog_Tasks&Times'!$H$110:$H$119,'Worklog_Tasks&Times'!$F$110:$F$119=$B6)),0)} -> 0 | I6: {=IFERROR(SUM(_xlfn._xlws.FILTER('Worklog_Tasks&Times'!$H$124:$H$133,'Worklog_Tasks&Times'!$F$124:$F$133=$B6)),0)} -> 0 | J6: {=IFERROR(SUM(_xlfn._xlws.FILTER('Worklog_Tasks&Times'!$H$138:$H$147,'Worklog_Tasks&Times'!$F$138:$F$147=$B6)),0)} -> 0 | K6: =SUM(C6:J6) -> 0
B7: ='Drop-downs'!C6 -> ILO 2.1 | C7: {=IFERROR(SUM(_xlfn._xlws.FILTER('Worklog_Tasks&Times'!$H$5:$H$22,'Worklog_Tasks&Times'!$F$5:$F$22=$B7)),0)} -> 0 | D7: {=IFERROR(SUM(_xlfn._xlws.FILTER('Worklog_Tasks&Times'!$H$27:$H$44,'Worklog_Tasks&Times'!$F$27:$F$44=$B7)),0)} -> 0 | E7: {=IFERROR(SUM(_xlfn._xlws.FILTER('Worklog_Tasks&Times'!$H$49:$H$62,'Worklog_Tasks&Times'!$F$49:$F$62=$B7)),0)} -> 0 | F7: {=IFERROR(SUM(_xlfn._xlws.FILTER('Worklog_Tasks&Times'!$H$67:$H$88,'Worklog_Tasks&Times'!$F$67:$F$88=$B7)),0)} -> 0 | G7: {=IFERROR(SUM(_xlfn._xlws.FILTER('Worklog_Tasks&Times'!$H$93:$H$105,'Worklog_Tasks&Times'!$F$93:$F$105=$B7)),0)} -> 0 | H7: {=IFERROR(SUM(_xlfn._xlws.FILTER('Worklog_Tasks&Times'!$H$110:$H$119,'Worklog_Tasks&Times'!$F$110:$F$119=$B7)),0)} -> 0 | I7: {=IFERROR(SUM(_xlfn._xlws.FILTER('Worklog_Tasks&Times'!$H$124:$H$133,'Worklog_Tasks&Times'!$F$124:$F$133=$B7)),0)} -> 0 | J7: {=IFERROR(SUM(_xlfn._xlws.FILTER('Worklog_Tasks&Times'!$H$138:$H$147,'Worklog_Tasks&Times'!$F$138:$F$147=$B7)),0)} -> 0 | K7: =SUM(C7:J7) -> 0
B8: ='Drop-downs'!C7 -> ILO 3.1 | C8: {=IFERROR(SUM(_xlfn._xlws.FILTER('Worklog_Tasks&Times'!$H$5:$H$22,'Worklog_Tasks&Times'!$F$5:$F$22=$B8)),0)} -> 22.25 | D8: {=IFERROR(SUM(_xlfn._xlws.FILTER('Worklog_Tasks&Times'!$H$27:$H$44,'Worklog_Tasks&Times'!$F$27:$F$44=$B8)),0)} -> 23 | E8: {=IFERROR(SUM(_xlfn._xlws.FILTER('Worklog_Tasks&Times'!$H$49:$H$62,'Worklog_Tasks&Times'!$F$49:$F$62=$B8)),0)} -> 18.5 | F8: {=IFERROR(SUM(_xlfn._xlws.FILTER('Worklog_Tasks&Times'!$H$67:$H$88,'Worklog_Tasks&Times'!$F$67:$F$88=$B8)),0)} -> 12.5 | G8: {=IFERROR(SUM(_xlfn._xlws.FILTER('Worklog_Tasks&Times'!$H$93:$H$105,'Worklog_Tasks&Times'!$F$93:$F$105=$B8)),0)} -> 7 | H8: {=IFERROR(SUM(_xlfn._xlws.FILTER('Worklog_Tasks&Times'!$H$110:$H$119,'Worklog_Tasks&Times'!$F$110:$F$119=$B8)),0)} -> 5 | I8: {=IFERROR(SUM(_xlfn._xlws.FILTER('Worklog_Tasks&Times'!$H$124:$H$133,'Worklog_Tasks&Times'!$F$124:$F$133=$B8)),0)} -> 4 | J8: {=IFERROR(SUM(_xlfn._xlws.FILTER('Worklog_Tasks&Times'!$H$138:$H$147,'Worklog_Tasks&Times'!$F$138:$F$147=$B8)),0)} -> 8 | K8: =SUM(C8:J8) -> 100.25
B9: ='Drop-downs'!C8 -> ILO 7.1 | C9: {=IFERROR(SUM(_xlfn._xlws.FILTER('Worklog_Tasks&Times'!$H$5:$H$22,'Worklog_Tasks&Times'!$F$5:$F$22=$B9)),0)} -> 0 | D9: {=IFERROR(SUM(_xlfn._xlws.FILTER('Worklog_Tasks&Times'!$H$27:$H$44,'Worklog_Tasks&Times'!$F$27:$F$44=$B9)),0)} -> 0 | E9: {=IFERROR(SUM(_xlfn._xlws.FILTER('Worklog_Tasks&Times'!$H$49:$H$62,'Worklog_Tasks&Times'!$F$49:$F$62=$B9)),0)} -> 0 | F9: {=IFERROR(SUM(_xlfn._xlws.FILTER('Worklog_Tasks&Times'!$H$67:$H$88,'Worklog_Tasks&Times'!$F$67:$F$88=$B9)),0)} -> 16.2 | G9: {=IFERROR(SUM(_xlfn._xlws.FILTER('Worklog_Tasks&Times'!$H$93:$H$105,'Worklog_Tasks&Times'!$F$93:$F$105=$B9)),0)} -> 8 | H9: {=IFERROR(SUM(_xlfn._xlws.FILTER('Worklog_Tasks&Times'!$H$110:$H$119,'Worklog_Tasks&Times'!$F$110:$F$119=$B9)),0)} -> 0 | I9: {=IFERROR(SUM(_xlfn._xlws.FILTER('Worklog_Tasks&Times'!$H$124:$H$133,'Worklog_Tasks&Times'!$F$124:$F$133=$B9)),0)} -> 3 | J9: {=IFERROR(SUM(_xlfn._xlws.FILTER('Worklog_Tasks&Times'!$H$138:$H$147,'Worklog_Tasks&Times'!$F$138:$F$147=$B9)),0)} -> 10 | K9: =SUM(C9:J9) -> 37.2
B10: ='Drop-downs'!C9 -> ILO 10.1 | C10: {=IFERROR(SUM(_xlfn._xlws.FILTER('Worklog_Tasks&Times'!$H$5:$H$22,'Worklog_Tasks&Times'!$F$5:$F$22=$B10)),0)} -> 0 | D10: {=IFERROR(SUM(_xlfn._xlws.FILTER('Worklog_Tasks&Times'!$H$27:$H$44,'Worklog_Tasks&Times'!$F$27:$F$44=$B10)),0)} -> 0 | E10: {=IFERROR(SUM(_xlfn._xlws.FILTER('Worklog_Tasks&Times'!$H$49:$H$62,'Worklog_Tasks&Times'!$F$49:$F$62=$B10)),0)} -> 0 | F10: {=IFERROR(SUM(_xlfn._xlws.FILTER('Worklog_Tasks&Times'!$H$67:$H$88,'Worklog_Tasks&Times'!$F$67:$F$88=$B10)),0)} -> 2 | G10: {=IFERROR(SUM(_xlfn._xlws.FILTER('Worklog_Tasks&Times'!$H$93:$H$105,'Worklog_Tasks&Times'!$F$93:$F$105=$B10)),0)} -> 4 | H10: {=IFERROR(SUM(_xlfn._xlws.FILTER('Worklog_Tasks&Times'!$H$110:$H$119,'Worklog_Tasks&Times'!$F$110:$F$119=$B10)),0)} -> 4 | I10: {=IFERROR(SUM(_xlfn._xlws.FILTER('Worklog_Tasks&Times'!$H$124:$H$133,'Worklog_Tasks&Times'!$F$124:$F$133=$B10)),0)} -> 0 | J10: {=IFERROR(SUM(_xlfn._xlws.FILTER('Worklog_Tasks&Times'!$H$138:$H$147,'Worklog_Tasks&Times'!$F$138:$F$147=$B10)),0)} -> 10 | K10: =SUM(C10:J10) -> 20
B11: TOTAL HOURS PER WEEK | C11: =SUM(C3:C10) -> 32.75 | D11: =SUM(D3:D10) -> 32 | E11: =SUM(E3:E10) -> 28.5 | F11: =SUM(F3:F10) -> 40.2 | G11: =SUM(G3:G10) -> 36.5 | H11: =SUM(H3:H10) -> 28.5 | I11: =SUM(I3:I10) -> 29 | J11: =SUM(J3:J10) -> 28
B13: Use this to plan a high level allocation for all 320 hours you are expected to devote to the course during this block. How do you want to allocate your hours for each week? Why 320 hours? The European Higher Education Framework states that an academic credit is expected to require 25-28 hours to earn. You earn 15 credits per block, so you should be expected to devote 375 hours to accomplish that. CMGT students do fewer hours because the program is more intense.
B17: If you add more rows to the Worklog Tasks and Time sheet, make sure to update the row count accordingly. For example, if you add an additional row for Week 1, you'll need to adjust all formula in Column C from H14 to H15 and F14 to F15

Sheet Drop-downs
A1: Task Status | B1: Task Type | C1: ILO selection
A2: - | B2: - | C2: -
A3: Planned | B3: Design | C3: ILO 0.1
A4: Unplanned | B4: Meeting | C4: ILO 0.2
A5: Blocked | B5: Programming | C5: ILO 1.1
A6: In-Progress | B6: Research | C6: ILO 2.1
A7: Done | B7: Testing | C7: ILO 3.1
A8: Delayed | B8: Workshop | C8: ILO 7.1
A9: Cancelled | B9: Planning | C9: ILO 10.1
B10: Evidencing
B11: Debugging
B12: Lecture
B13: Study
B14: Unplanned
B15: Distraction
B16: Break
